Workbook

Sheet Participant List
H1: Availability
A2: Name | B2: Initials | C2: Email | D2: Phone | E2: Affiliation | F2: Notes | H2: 45480 | I2: 45481 | J2: 45482 | K2: 45483 | L2: 45484 | M2: 45485 | N2: 45486 | O2: 45487 | P2: 45488 | Q2: 45489
A3: Dhruval Shah | B3: DS | C3: dsi491@uregina.ca | E3: U Regina
A4: Mira Rupert | B4: QMR | C4: qmr444@uregina.ca | E4: U Regina
A5: Jizhong Liu | B5: JL | C5: jln098@uregina.ca | D5: 403-397-1582 | E5: U Regina
A6: Eric Gyabeng Fuakye | B6: EGF | C6: efk382@uregina.ca | E6: U Regina
A7: Gwen Grinyer | B7: GG | C7: Gwen.Grinyer@uregina.ca | D7: 306-201-5548 | E7: U Regina
A8: Sydney Plante | B8: SP | C8: sydneyplante@hotmail.com | E8: U Regina
A9: Chris Griffin | B9: CJG | C9: cgriffin@triumf.ca | D9: 236 979 3266 | E9: TRIUMF
A10: Vinzenz Bildstein | B10: VB | C10: vbildste@uoguelph.ca | E10: U Guelph
A11: Iris Dillmann | B11: ID | C11: dillmann@triumf.ca | E11: TRIUMF, UVic
A12: Carl Svensson | B12: CES | C12: sven@uoguelph.ca | E12: U Guelph
A13: Maeve Cockshutt | B13: MEC | C13: mcockshutt@triumf.ca | E13: TRIUMF, UVic
A14: Shaun Georges | B14: SG | C14: sgeorges@triumf.ca | E14: TRIUMF
A15: Annabelle Grimes | B15: ALG | C15: agrimes@triumf.ca | D15: (613) 601-8456 | E15: TRIUMF, UBC
A16: Ethan Geerlof | B16: EDG | C16: egeerlof@triumf.ca | D16: (236) 591-3054 | E16: TRIUMF, UBC | F16: Whatsapp: same
A17: Silvia Murillo Morales | B17: SMM | C17: smurillo@triumf.ca | D17: 6723383141 | E17: TRIUMF LOCAL
A18: Javier R. Murias | B18: JRM | C18: jrodriguez@triumf.ca | D18: 2367778710 | E18: TRIUMF LOCAL | F18: Whatsapp: +34 650838667
A19: Abraham Aungwa Avaa | B19: AAA | C19: aavaa@triumf.ca | D19: 236-866-1589 | E19: TRIUMF LOCAL
A20: Addison Calder | B20: ABC | C20: addisonb@uoguelph.ca | D20: 905-327-4409 | E20: U Guelph
A21: Ethan McCourt | B21: EM | C21: emccourt@uoguelph.ca | D21: 2269892146 | E21: U Guelph
A22: Rashmi Umashankar | B22: RU | C22: rumashankar@triumf.ca | D22: 2265078336 | E22: TRIUMF/UBC
A23: Gordon Ball | B23: GCB | C23: ball@triumf.ca | E23: TRIUMF
A24: Victoria Vedia | B24: VV | C24: vvedia@triumf.ca | D24: 236-978-3439 | E24: TRIUMF LOCAL

Sheet Shift Schedule
D2: Friday | I2: Wednesday
B3: Shift | C3: Time (PDT) | D3: May 27th | E3: 45484 | F3: 45485 | G3: 45486 | H3: 45487 | I3: June 1st
B4: OWL | C4: 00:00-08:00 | E4: Setup | F4: JL | G4: EGF | H4: EGF
E5: Setup | J5: `
B6: DAY | C6: 08:00-16:00 | E6: Setup | F6: ALG, JRM | G6: EM | H6: EM, GG
D7: --- | E7: Setup | F7: EDG | G7: ABC | H7: ABC
B8: EVE | C8: 16:00-00:00 | E8: ABC | F8: QMR, SP | G8: SP
E9: GG | F9: DS | G9: DS
G13: L

Sheet Run Log
B1: S2232: Delayed charged particle spectroscopy of 20Mg
B2: Experiment run log (green = data, blue = calibration, red = junk)
A3: sub-runs | B3: Sort | C3: HistA | D3: CalA | E3: HistR | F3: Date | G3: Run Number | H3: Start | I3: Stop | J3: Duration | K3: Trigger | L3: Current (uA) | M3: Data | N3: Notes
A4: 0 | B4: TRUE | C4: TRUE | D4: FALSE | E4: TRUE | F4: 45476 | G4: 28183 | H4: 0.59017361 | I4: 0.59172454 | J4: =I4-H4 -> 0.0015509259 | K4: RCMP | L4: n/a | M4: cal | N4: Triple alpha source, array closed (RCS01N and RCS04P are off)
A5: 0 | B5: TRUE | C5: TRUE | D5: FALSE | E5: FALSE | F5: 45476 | G5: 28184 | H5: 0.59292824 | I5: 0.59988426 | J5: =I5-H5 -> 0.0069560185 | K5: RCMP | L5: n/a | M5: cal | N5: Triple alpha source, array closed (RCS01N and RCS04P are off)
A6: 0 | B6: TRUE | C6: TRUE | D6: FALSE | E6: FALSE | F6: 45476 | G6: 28185 | H6: 0.60295139 | I6: 0.64462963 | J6: =I6-H6 -> 0.041678241 | K6: RCMP | L6: n/a | M6: cal | N6: Triple alpha source, array closed (RCS01N and RCS04P are off)
A7: 0 | B7: TRUE | C7: TRUE | D7: FALSE | E7: FALSE | F7: 45478 | G7: 28204 | H7: 0.95048611 | I7: 0.97133102 | J7: =I7-H7 -> 0.020844907 | K7: RCMP | L7: n/a | M7: cal | N7: Triple alpha source, RCMP signal check (RCS06 disabled)
A8: 0-5 | B8: TRUE | C8: TRUE | D8: FALSE | E8: FALSE | F8: 45478 | G8: 28205 | H8: 0.99302083 | I8: 0.32636574 | J8: 0.33334491 | K8: RCMP | L8: n/a | M8: cal | N8: Triple alpha source, RCMP signal check (RCS06 disabled)
A9: 0 | B9: TRUE | C9: TRUE | D9: FALSE | E9: FALSE | F9: 45479 | G9: 28206 | H9: 0.76171296 | I9: 0.83018519 | J9: =I9-H9 -> 0.068472222 | K9: RCMP | L9: n/a | M9: cal | N9: Triple alpha source, RCMP signal check
A10: 0-2 | B10: TRUE | C10: TRUE | D10: FALSE | E10: FALSE | F10: 45479 | G10: 28213 | H10: 0.92641204 | I10: 0.014953704 | J10: 0.088541667 | K10: RCMP | L10: n/a | M10: cal | N10: Triple alpha source, RCMP signal check
A11: 0-6 | B11: TRUE | C11: TRUE | D11: FALSE | E11: TRUE | F11: 45480 | G11: 28214 | H11: 0.015185185 | I11: 0.34851852 | J11: =I11-H11 -> 0.33333333 | K11: RCMP | L11: n/a | M11: cal | N11: Triple alpha source, RCMP signal checking
A12: 0 | B12: TRUE | C12: TRUE | D12: FALSE | E12: FALSE | F12: 45481 | G12: 28217 | H12: 0.62444444 | I12: 0.63140046 | J12: =I12-H12 -> 0.0069560185 | K12: BGO | L12: n/a | M12: cal | N12: 137Cs source, BGO Gainmatching, position 13 check
A13: 0-1 | B13: TRUE | C13: TRUE | D13: FALSE | E13: FALSE | F13: 45481 | G13: 28218 | H13: 0.64789352 | I13: 0.65136574 | J13: =I13-H13 -> 0.0034722222 | K13: BGO | L13: n/a | M13: cal | N13: 137Cs source, BGO Gainmatching, position 13 check
A14: 0-1 | B14: TRUE | C14: TRUE | D14: FALSE | E14: FALSE | F14: 45481 | G14: 28223 | H14: 0.68076389 | I14: 0.68423611 | J14: =I14-H14 -> 0.0034722222 | K14: BGO | L14: n/a | M14: cal | N14: 137Cs source, BGO Gainmatching, position 13 check
A15: 0-14 | B15: TRUE | C15: TRUE | D15: FALSE | E15: FALSE | F15: 45481 | G15: 28226 | H15: 0.7218287 | I15: 0.30517361 | J15: 0.58334491 | K15: RCMP | L15: n/a | M15: cal | N15: Triple alpha source, R00968 | O15: Matches ELOG
A16: 0 | B16: TRUE | C16: TRUE | D16: FALSE | E16: FALSE | F16: 45482 | G16: 28227 | H16: 0.44211806 | I16: 0.45787037 | J16: =I16-H16 -> 0.015752315 | K16: RCMP | L16: n/a | M16: cal | N16: Triple alpha source single sided, Mylar test, R00868 (Mylar off source only)
A17: 0-5 | B17: TRUE | C17: TRUE | D17: FALSE | E17: FALSE | F17: 45482 | G17: 28228 | H17: 0.50393519 | I17: 0.56295139 | J17: =I17-H17 -> 0.059016204 | K17: RCMP | L17: n/a | M17: cal | N17: Triple alpha source single sided, Mylar test, R00868 (0.5um Mylar installed)
A18: 0-57 | B18: TRUE | C18: TRUE | D18: FALSE | E18: FALSE | F18: 45482 | G18: 28229 | H18: 0.56453704 | I18: 0.57211806 | J18: =I18-H18 -> 0.0075810185 | K18: GRIFFIN | L18: n/a | M18: cal | N18: HPGe and LaBr3 energy efficiency calibration, RCMP off, 207bl, R01197, 1.865MBq
A19: 0-25 | B19: TRUE | C19: TRUE | D19: FALSE | E19: FALSE | F19: 45482 | G19: 28230 | H19: 0.57225694 | I19: 0.57564815 | J19: =I19-H19 -> 0.0033912037 | K19: GRIFFIN | L19: n/a | M19: cal | N19: HPGe and LaBr3 energy efficiency calibration, RCMP off, 207bl, R01197, 1.865MBq
A20: 0-5 | B20: TRUE | C20: TRUE | D20: FALSE | E20: FALSE | F20: 45482 | G20: 28235 | H20: 0.64939815 | I20: 0.65009259 | J20: =I20-H20 -> 0.00069444444 | K20: GRIFFIN | L20: n/a | M20: cal | N20: 207Bi source, energy and efficiency calibration, RCMP off, R01197, 1.865MBq
A21: 0 | B21: TRUE | C21: TRUE | D21: FALSE | E21: FALSE | F21: 45482 | G21: 28236 | H21: 0.65403935 | I21: 0.65417824 | J21: =I21-H21 -> 0.00013888889 | K21: GRIFFIN | L21: n/a | M21: cal | N21: 60Co source, energy and efficiency calibration, RCMP off, R01105, 3.82e+04Bq
A22: 0-10 | B22: TRUE | C22: TRUE | D22: FALSE | E22: FALSE | F22: 45482 | G22: 28237 | H22: 0.65423611 | I22: 0.77923611 | J22: =I22-H22 -> 0.125 | K22: GRIFFIN | L22: n/a | M22: cal | N22: 60Co source, energy and efficiency calibration, RCMP off, R01105, 3.82e+04Bq
A23: 0-9 | B23: TRUE | C23: TRUE | D23: FALSE | E23: FALSE | F23: 45482 | G23: 28238 | H23: 0.78340278 | I23: 0.80423611 | J23: =I23-H23 -> 0.020833333 | K23: GRIFFIN | L23: n/a | M23: cal | N23: 56Co source, energy and efficiency calibration, RCMP off, R01274, 300kBq
A24: 0-1 | B24: TRUE | C24: TRUE | D24: FALSE | E24: FALSE | F24: 45482 | G24: 28239 | H24: 0.8106713 | I24: 0.85234954 | J24: =I24-H24 -> 0.041678241 | K24: GRIFFIN | L24: n/a | M24: cal | N24: 60Co source, energy and efficiency calibration, RCMP off, R00793, 3.85e-04Bq
A25: 0-4 | B25: TRUE | C25: TRUE | D25: FALSE | E25: FALSE | F25: 45482 | G25: 28240 | H25: 0.8678125 | I25: 0.95114583 | J25: =I25-H25 -> 0.083333333 | K25: GRIFFIN | L25: n/a | M25: cal | N25: 133Ba source, energy and efficiency calibration, RCMP off, 3.88e+04Bq
A26: 0-11 | B26: TRUE | C26: TRUE | D26: FALSE | E26: FALSE | F26: 45482 | G26: 28241 | H26: 0.97881944 | I26: 0.35384259 | J26: 0.37502315 | K26: RCMP | L26: n/a | M26: cal | N26: Alpha source, 241Am 244Cm 289Pu, verticle source holder, RCMP on, 1.11e+03Bq
A27: 0 | B27: TRUE | C27: TRUE | D27: FALSE | E27: FALSE | F27: 45483 | G27: 28242 | H27: 0.37944444 | I27: 0.38056713 | J27: =I27-H27 -> 0.0011226852 | K27: GRIFFIN | L27: n/a | M27: cal | N27: 152Eu source, energy and efficiency calibration, RCMP off, R1103, 3.98e+04Bq
A28: 0-14 | B28: TRUE | C28: TRUE | D28: FALSE | E28: FALSE | F28: 45483 | G28: 28243 | H28: 0.38082176 | I28: 0.50582176 | J28: =I28-H28 -> 0.125 | K28: GRIFFIN | L28: n/a | M28: cal | N28: 152Eu source, energy and efficiency calibration, RCMP off, R1103, 3.94e+04Bq
A29: 0-3 | B29: TRUE | C29: TRUE | D29: FALSE | E29: FALSE | F29: 45483 | G29: 28246 | H29: 0.52792824 | I29: 0.53488426 | J29: =I29-H29 -> 0.0069560185 | K29: GRIFFIN | L29: n/a | M29: cal | N29: 224Cm/13C -> 16O*, energy callibration, RCMP off
A30: 0-1 | B30: TRUE | C30: TRUE | D30: FALSE | E30: FALSE | F30: 45483 | G30: 28249 | H30: 0.56982639 | I30: 0.5802662 | J30: =I30-H30 -> 0.010439815 | K30: RCMP | L30: n/a | M30: cal | N30: 207Bi source, beta calibration, RCMP on, R00758, 4.07e+04Bq, vacuum on, face upstream
A31: 0 | B31: TRUE | C31: TRUE | D31: FALSE | E31: FALSE | F31: 45483 | G31: 28250 | H31: 0.58086806 | I31: 0.58155093 | J31: =I31-H31 -> 0.00068287037 | K31: RCMP | L31: n/a | M31: cal | N31: 207Bi source, beta calibration, RCMP on, R00758, 4.07e+04Bq, vacuum on, face upstream
A32: 0-8 | B32: TRUE | C32: TRUE | D32: FALSE | E32: FALSE | F32: 45483 | G32: 28251 | H32: 0.58263889 | I32: 0.62431713 | J32: =I32-H32 -> 0.041678241 | K32: RCMP | L32: n/a | M32: cal | N32: 207Bi source, beta calibration, RCMP on, R00758, 4.07e+04Bq, vacuum on, face upstream
A33: 0-7 | B33: TRUE | C33: TRUE | D33: FALSE | E33: FALSE | F33: 45483 | G33: 28252 | H33: 0.62890046 | I33: 0.6705787 | J33: =I33-H33 -> 0.041678241 | K33: RCMP | L33: n/a | M33: cal | N33: 207Bi source, beta calibration, RCMP on, R00758, 4.07e+04Bq, vacuum on, face upstream
A34: 0 | B34: TRUE | C34: TRUE | D34: FALSE | E34: FALSE | F34: 45483 | G34: 28253 | H34: 0.67658565 | I34: 0.67667824 | J34: =I34-H34 -> 9.2592593e-05 | K34: GRIFFIN | L34: n/a | M34: cal | N34: 224Cm/13C -> 16O*, energy callibration, RCMP off
A35: 0-30 | B35: TRUE | C35: TRUE | D35: FALSE | E35: FALSE | F35: 45483 | G35: 28254 | H35: 0.67704861 | I35: 0.69094907 | J35: =I35-H35 -> 0.013900463 | K35: GRIFFIN | L35: n/a | M35: cal | N35: 224Cm/13C -> 16O*, energy callibration, RCMP off
A36: 0-2 | B36: TRUE | C36: FALSE | D36: FALSE | E36: FALSE | F36: 45484 | G36: 28255 | H36: 0.59858796 | I36: 0.72288194 | J36: =I36-H36 -> 0.12429398 | K36: GRIFFIN | L36: 50 uA | M36: cal | N36: Background gamma singles
A37: 1 | B37: FALSE | C37: FALSE | D37: FALSE | E37: FALSE | F37: 45484 | G37: 28256 | H37: 0.72649306 | I37: 0.73047454 | J37: =I37-H37 -> 0.0039814815 | K37: singles | L37: 50 uA | M37: junk | N37: Kicker test, cup is in so no beam (1 s on, 5 s off)
A38: 1 | B38: FALSE | C38: FALSE | D38: FALSE | E38: FALSE | F38: 45484 | G38: 28257 | H38: 0.73097222 | I38: 0.73199074 | J38: =I38-H38 -> 0.0010185185 | K38: singles | L38: 50 uA | M38: junk | N38: Kicker test, cup is in so no beam (continuous beam on)
A39: 1 | B39: FALSE | C39: FALSE | D39: FALSE | E39: FALSE | F39: 45484 | G39: 28258 | H39: 0.73206019 | I39: 0.73362269 | J39: =I39-H39 -> 0.0015625 | K39: singles | L39: 50 uA | M39: junk | N39: Kicker test, cup is in so no beam (continuous beam on)
A40: 1 | B40: FALSE | C40: FALSE | D40: FALSE | E40: FALSE | F40: 45484 | G40: 28259 | H40: 0.73416667 | I40: 0.73627315 | J40: =I40-H40 -> 0.0021064815 | K40: singles | L40: 50 uA | M40: junk | N40: Kicker test, cup is in so no beam (test kicker cycle file)
...

Sheet Rates
A1: 1
A2: Beam intensity calculations based on the gamma-ray activity (use spectrum viewer)
A4: Eff (984 keV) | B4: 0.085 | C4: Eff (1633 keV) | D4: 0.06
A5: BR (984 keV) | B5: 0.7 | C5: BR (1633 keV) | D5: 0.8
I6: Ratio (I 20Na in beam) /
A7: Run | B7: Run Time | C7: N(984 keV) | D7: N(1633 keV) | E7: Duty Factor | F7: I (20Mg) | G7: I (20Na) | H7: I (20Na) (In-beam) | I7: (I 20 Mg)
A8: 28269 | B8: =23*60+42 -> 1422 | C8: 884353 | D8: 754843 | E8: =55/60 -> 0.91666667 | F8: =C8/B8/E8/$B$4/$B$5 -> 11402.436 | G8: =D8/B8/E8/$D$4/$D$5 -> 12064.362 | H8: =G8-(F8*$B$5) -> 4082.6566 | I8: =H8/F8 -> 0.35805126
A9: 28270 | B9: 736 | C9: 485515 | D9: 403335 | E9: =55/60 -> 0.91666667 | F9: =C9/B9/E9/$B$4/$B$5 -> 12094.737 | G9: =D9/B9/E9/$D$4/$D$5 -> 12454.762 | H9: =G9-(F9*$B$5) -> 3988.4456 | I9: =H9/F9 -> 0.32976704
A10: 28271 | B10: 807 | C10: 539157 | D10: 460254 | E10: =55/60 -> 0.91666667 | F10: =C10/B10/E10/$B$4/$B$5 -> 12249.357 | G10: =D10/B10/E10/$D$4/$D$5 -> 12961.98 | H10: =G10-(F10*$B$5) -> 4387.4302 | I10: =H10/F10 -> 0.35817635
A11: 28272 | B11: 618 | C11: 402546 | D11: 323035 | E11: =55/60 -> 0.91666667 | F11: =C11/B11/E11/$B$4/$B$5 -> 11942.593 | G11: =D11/B11/E11/$D$4/$D$5 -> 11879.781 | H11: =G11-(F11*$B$5) -> 3519.9656 | I11: =H11/F11 -> 0.29474048
A12: 28273 | B12: 674 | C12: 388097 | D12: 332117 | E12: =55/60 -> 0.91666667 | F12: =C12/B12/E12/$B$4/$B$5 -> 10557.279 | G12: =D12/B12/E12/$D$4/$D$5 -> 11198.982 | H12: =G12-(F12*$B$5) -> 3808.8866 | I12: =H12/F12 -> 0.36078299
A13: 28274 | B13: 516 | C13: 292790 | D13: 253846 | E13: =55/60 -> 0.91666667 | F13: =C13/B13/E13/$B$4/$B$5 -> 10403.468 | G13: =D13/B13/E13/$D$4/$D$5 -> 11180.673 | H13: =G13-(F13*$B$5) -> 3898.2455 | I13: =H13/F13 -> 0.37470635
A14: 28275 | B14: 581 | C14: 345672 | D14: 328072 | E14: =55/60 -> 0.91666667 | F14: =C14/B14/E14/$B$4/$B$5 -> 10908.365 | G14: =D14/B14/E14/$D$4/$D$5 -> 12833.359 | H14: =G14-(F14*$B$5) -> 5197.5038 | I14: =H14/F14 -> 0.47646955
A15: 28276 | B15: 900 | C15: 534228 | D15: 473740 | E15: =55/60 -> 0.91666667 | F15: =C15/B15/E15/$B$4/$B$5 -> 10883.178 | G15: =D15/B15/E15/$D$4/$D$5 -> 11963.131 | H15: =G15-(F15*$B$5) -> 4344.9067 | I15: =H15/F15 -> 0.39923143
A16: 28280 | B16: 300 | C16: 2529 | D16: 11874 | E16: =55/60 -> 0.91666667 | F16: =C16/B16/E16/$B$4/$B$5 -> 154.56073 | G16: =D16/B16/E16/$D$4/$D$5 -> 899.54545 | H16: =G16-(F16*$B$5) -> 791.35294 | I16: =H16/F16 -> 5.1200129
A17: 28281 | B17: 1137 | C17: 334371 | D17: 292386 | E17: =55/60 -> 0.91666667 | F17: =C17/B17/E17/$B$4/$B$5 -> 5391.874 | G17: =D17/B17/E17/$D$4/$D$5 -> 5844.4471 | H17: =G17-(F17*$B$5) -> 2070.1353 | I17: =H17/F17 -> 0.38393614
A18: 28282 | B18: 3600 | C18: 1330658 | D18: 1030272 | E18: =55/60 -> 0.91666667 | F18: =C18/B18/E18/$B$4/$B$5 -> 6776.9697 | G18: =D18/B18/E18/$D$4/$D$5 -> 6504.2424 | H18: =G18-(F18*$B$5) -> 1760.3636 | I18: =H18/F18 -> 0.25975675
A19: 28283 | B19: 3601 | C19: 1421691 | D19: 1126972 | E19: =55/60 -> 0.91666667 | F19: =C19/B19/E19/$B$4/$B$5 -> 7238.5852 | G19: =D19/B19/E19/$D$4/$D$5 -> 7112.7465 | H19: =G19-(F19*$B$5) -> 2045.7368 | I19: =H19/F19 -> 0.28261557
A20: 28284 | B20: 3600 | C20: 1424592 | D20: 1108675 | E20: =55/60 -> 0.91666667 | F20: =C20/B20/E20/$B$4/$B$5 -> 7255.3705 | G20: =D20/B20/E20/$D$4/$D$5 -> 6999.2109 | H20: =G20-(F20*$B$5) -> 1920.4515 | I20: =H20/F20 -> 0.26469379
... A22: 28286 | B22: 3600 | C22: 1445517 | D22: 1235141 | E22: =55/60 -> 0.91666667 | F22: =C22/B22/E22/$B$4/$B$5 -> 7361.9404 | G22: =D22/B22/E22/$D$4/$D$5 -> 7797.6073 | H22: =G22-(F22*$B$5) -> 2644.249 | I22: =H22/F22 -> 0.35917827
A23: 28287 | B23: =35*60 -> 2100 | C23: 822032.65 | D23: 669884.73 | E23: =55/60 -> 0.91666667 | F23: =C23/B23/E23/$B$4/$B$5 -> 7176.9739 | G23: =D23/B23/E23/$D$4/$D$5 -> 7249.8347 | H23: =G23-(F23*$B$5) -> 2225.953 | I23: =H23/F23 -> 0.31015203
A24: 28288 | B24: =11*60 -> 660 | C24: 236048.15 | D24: 196911.15 | E24: =55/60 -> 0.91666667 | F24: =C24/B24/E24/$B$4/$B$5 -> 6557.3484 | G24: =D24/B24/E24/$D$4/$D$5 -> 6780.687 | H24: =G24-(F24*$B$5) -> 2190.5431 | I24: =H24/F24 -> 0.33405928
A25: 28290 | B25: =8*60 -> 480 | C25: 187497.36 | D25: 154456.96 | E25: =55/60 -> 0.91666667 | F25: =C25/B25/E25/$B$4/$B$5 -> 7161.8549 | G25: =D25/B25/E25/$D$4/$D$5 -> 7313.303 | H25: =G25-(F25*$B$5) -> 2300.0046 | I25: =H25/F25 -> 0.3211465
A26: 28292 | B26: =14*60 -> 840 | C26: 326939.24 | D26: 274685.39 | E26: =55/60 -> 0.91666667 | F26: =C26/B26/E26/$B$4/$B$5 -> 7136.0742 | G26: =D26/B26/E26/$D$4/$D$5 -> 7431.964 | H26: =G26-(F26*$B$5) -> 2436.7121 | I26: =H26/F26 -> 0.34146395
A27: 28293 | B27: =14*60 -> 840 | C27: 317945.05 | D27: 270833.43 | E27: =55/60 -> 0.91666667 | F27: =C27/B27/E27/$B$4/$B$5 -> 6939.7588 | G27: =D27/B27/E27/$D$4/$D$5 -> 7327.7443 | H27: =G27-(F27*$B$5) -> 2469.9131 | I27: =H27/F27 -> 0.35590764
A28: 28294 | B28: =14*60 -> 840 | C28: 350347.78 | D28: 293760.68 | E28: =55/60 -> 0.91666667 | F28: =C28/B28/E28/$B$4/$B$5 -> 7647.0104 | G28: =D28/B28/E28/$D$4/$D$5 -> 7948.0703 | H28: =G28-(F28*$B$5) -> 2595.1631 | I28: =H28/F28 -> 0.33936963
A29: 28296 | B29: 3600 | C29: 1334140.6 | D29: 1139869.8 | E29: =55/60 -> 0.91666667 | F29: =C29/B29/E29/$B$4/$B$5 -> 6794.7063 | G29: =D29/B29/E29/$D$4/$D$5 -> 7196.1477 | H29: =G29-(F29*$B$5) -> 2439.8532 | I29: =H29/F29 -> 0.35908148
A30: 28297 | B30: 3600 | C30: 1327802.1 | D30: 1196818.3 | E30: =55/60 -> 0.91666667 | F30: =C30/B30/E30/$B$4/$B$5 -> 6762.4245 | G30: =D30/B30/E30/$D$4/$D$5 -> 7555.6711 | H30: =G30-(F30*$B$5) -> 2821.974 | I30: =H30/F30 -> 0.4173021
A31: 28298 | B31: =3600+21 -> 3621 | C31: 1308199.2 | D31: 1265746.5 | E31: =55/60 -> 0.91666667 | F31: =C31/B31/E31/$B$4/$B$5 -> 6623.9487 | G31: =D31/B31/E31/$D$4/$D$5 -> 7944.4809 | H31: =G31-(F31*$B$5) -> 3307.7169 | I31: =H31/F31 -> 0.49935726
A32: 28299 | B32: 3600 | C32: 1225618.5 | D32: 1278667.3 | E32: =55/60 -> 0.91666667 | F32: =C32/B32/E32/$B$4/$B$5 -> 6242.0092 | G32: =D32/B32/E32/$D$4/$D$5 -> 8072.3947 | H32: =G32-(F32*$B$5) -> 3702.9882 | I32: =H32/F32 -> 0.59323659 | K32: keV | M32: 16B00A | N32: 16G00A | O32: 16R00A | P32: 16W00A | Q32: 15W00A
A33: 28300 | B33: 3600 | C33: 1204722 | D33: 1456080 | E33: =55/60 -> 0.91666667 | F33: =C33/B33/E33/$B$4/$B$5 -> 6135.5844 | G33: =D33/B33/E33/$D$4/$D$5 -> 9192.4242 | H33: =G33-(F33*$B$5) -> 4897.5152 | I33: =H33/F33 -> 0.79821494 | J33: E1 | K33: 511 | M33: 393 | N33: 409 | O33: 398 | P33: 403 | Q33: 411
A34: 28301 | B34: 3325 | C34: 1085843.6 | D34: 1405391.9 | E34: =55/60 -> 0.91666667 | F34: =C34/B34/E34/$B$4/$B$5 -> 5987.5233 | G34: =D34/B34/E34/$D$4/$D$5 -> 9606.2334 | H34: =G34-(F34*$B$5) -> 5414.967 | I34: =H34/F34 -> 0.90437511 | J34: E2 | K34: 1633 | M34: 1259 | N34: 1309 | O34: 1273 | P34: 1289 | Q34: 1317
A35: 28302 | B35: 1794 | C35: 542938.92 | D35: 873297.67 | E35: =55/60 -> 0.91666667 | F35: =C35/B35/E35/$B$4/$B$5 -> 5548.8135 | G35: =D35/B35/E35/$D$4/$D$5 -> 11063.364 | H35: =G35-(F35*$B$5) -> 7179.1941 | I35: =H35/F35 -> 1.2938251
A36: 28304 | B36: 420 | C36: 139053 | D36: 131856 | E36: =55/60 -> 0.91666667 | F36: =C36/B36/E36/$B$4/$B$5 -> 6070.1954 | G36: =D36/B36/E36/$D$4/$D$5 -> 7135.0649 | H36: =G36-(F36*$B$5) -> 2885.9282 | I36: =H36/F36 -> 0.47542592 | L36: 28326 | M36: =($K$34-$K$33)/(M34-M33) -> 1.295612 | N36: =($K$34-$K$33)/(N34-N33) -> 1.2466667 | O36: =($K$34-$K$33)/(O34-O33) -> 1.2822857 | P36: =($K$34-$K$33)/(P34-P33) -> 1.2663657 | Q36: =($K$34-$K$33)/(Q34-Q33) -> 1.2384106
A37: 28306 | B37: 361 | C37: 103406.2 | D37: 98448.38 | E37: =55/60 -> 0.91666667 | F37: =C37/B37/E37/$B$4/$B$5 -> 5251.8338 | G37: =D37/B37/E37/$D$4/$D$5 -> 6197.959 | H37: =G37-(F37*$B$5) -> 2521.6753 | I37: =H37/F37 -> 0.48015139 | L37: offset | M37: =$K$34-M36*M34 -> 1.8244804 | N37: =$K$34-N36*N34 -> 1.1133333 | O37: =$K$34-O36*O34 -> 0.65028571 | P37: =$K$34-P36*P34 -> 0.65462754 | Q37: =$K$34-Q36*Q34 -> 2.013245
A38: 28307 | B38: =42*60 -> 2520 | C38: 737674 | D38: 777950 | E38: =55/60 -> 0.91666667 | F38: =C38/B38/E38/$B$4/$B$5 -> 5367.0486 | G38: =D38/B38/E38/$D$4/$D$5 -> 7016.1436 | H38: =G38-(F38*$B$5) -> 3259.2095 | I38: =H38/F38 -> 0.6072629
A39: 28308 | B39: 2115 | C39: 592436.38 | D39: 751967.41 | E39: =55/60 -> 0.91666667 | F39: =C39/B39/E39/$B$4/$B$5 -> 5135.739 | G39: =D39/B39/E39/$D$4/$D$5 -> 8080.4579 | H39: =G39-(F39*$B$5) -> 4485.4406 | I39: =H39/F39 -> 0.87337783
A40: 28309 | B40: 3408 | C40: 937718.35 | D40: 1603410.5 | E40: =55/60 -> 0.91666667 | F40: =C40/B40/E40/$B$4/$B$5 -> 5044.8055 | G40: =D40/B40/E40/$D$4/$D$5 -> 10692.825 | H40: =G40-(F40*$B$5) -> 7161.4615 | I40: =H40/F40 -> 1.4195714
A41: 28310 | B41: 1186 | C41: 335649.09 | D41: 646427.72 | E41: =55/60 -> 0.91666667 | F41: =C41/B41/E41/$B$4/$B$5 -> 5188.8651 | G41: =D41/B41/E41/$D$4/$D$5 -> 12387.47 | H41: =G41-(F41*$B$5) -> 8755.2642 | I41: =H41/F41 -> 1.6873177
A42: 28311 | B42: 2003 | C42: 506959.64 | D42: 1476601.3 | E42: =55/60 -> 0.91666667 | F42: =C42/B42/E42/$B$4/$B$5 -> 4640.492 | G42: =D42/B42/E42/$D$4/$D$5 -> 16754.429 | H42: =G42-(F42*$B$5) -> 13506.084 | I42: =H42/F42 -> 2.9104854
...

Sheet Calcs
A1: Calculations
A2: Quick calculations, constants, and atomic masses
H3: 20Mg gamma spectrum from run 28263
A4: Isotope | B4: Mass (amu) | H4: Egamma | J4: No lasers
A5: 20Mg | B5: 20.018763 | D5: delta M (amu) | E5: =B5-B6 -> 0.011408774 | H5: 139 | I5: weak | J5: 139 | K5: N
A6: 20Na | B6: 20.007354 | D6: delta M/M | E6: =E5/B5 -> 0.00056990404 | H6: 197 | I6: weak | J6: 197 | K6: N
H7: 238 | K7: Y
A8: Rates | H8: 275 | K8: Y
A9: Half-life (20Mg) | B9: 0.091 | C9: s | H9: 511 | K9: Y
A10: Lambda (20Mg) | B10: =LN(2)/B9 -> 7.617002 | C10: 1/s | H10: 596 | I10: weak | K10: Y
A11: Beam Intensity | B11: 7000 | C11: Mg/s | H11: 610 | I11: weak | K11: Y
A12: Beam on | B12: 0.2 | C12: s | H12: 789 | K12: Y
A13: Activity | B13: =B11*(1-EXP(-B10*B12)) -> 5474.2139 | H13: 984 | K13: Y
A14: N implanted | B14: =B11*B12-B11/B10*(1-EXP(-B10*B12)) -> 681.31647 | H14: 1122 | K14: Y | L14: 1233
H15: 1295 | I15: doublet | K15: N
B16: Run 28262 | E16: Run 28264 | H16: 1298 | I16: doublet | K16: Y
A17: N(984) | B17: 83486 | C17: 352702 | D17: N(1633) | E17: 20245 | F17: 22940 | H17: 1436 | I17: LaBr3 | K17: Y
A18: efficiency | B18: 0.085 | C18: 0.085 | E18: 0.06 | F18: 0.06 | H18: 1460 | I18: 40K | K18: Y
A19: branch | B19: 0.7 | C19: 0.7 | E19: =0.8 -> 0.8 | F19: =0.8 -> 0.8 | H19: 1633 | J19: 1633 | K19: Y
A20: run time | B20: 667 | C20: =46*60+56 -> 2816 | E20: =11*60+13 -> 673 | F20: =12*60+50 -> 770 | H20: 1765 | I20: weak | K20: N
A21: on/off | B21: =1/6*B20 -> 111.16667 | C21: =1/6*C20 -> 469.33333 | E21: =1/6*E20 -> 112.16667 | F21: =1/6*F20 -> 128.33333 | H21: 1779 | I21: weak | K21: N
H22: 2144 | K22: Y
H23: 2205 | K23: N
A24: Intensity (20Mg) | B24: =B17/B21/B19/B18 -> 12621.824 | C24: =C17/C21/C19/C18 -> 12630.18 | E24: =E17/E21/E19/E18 -> 3760.2155 | F24: =F17/F21/F19/F18 -> 3724.026 | H24: 2615 | I24: 208Pb | K24: Y
H25: 4238 | I25: weak | K25: N
A26: Run 28266 | E26: Run 28266
A27: N(984) | B27: 252413 | D27: N(1633) | E27: 214741
A28: efficiency | B28: 0.085 | E28: 0.06
A29: branch | B29: 0.7 | E29: =0.8 -> 0.8
A30: run time | B30: =34*60+40 -> 2080 | E30: =34*60+40 -> 2080
A31: on/off | B31: =1/6*B30 -> 346.66667 | E31: =1/6*E30 -> 346.66667
A34: Intensity (20Mg) | B34: =B27/B31/B29/B28 -> 12237.217 | E34: =E27/E31/E29/E28 -> 12905.108
E35: =E34-(0.7*B34) -> 4339.0561

Sheet Leakage
A1: Leakage Currents | E1: Graph will auto-fill. No need to change.
A2: Run by run leakage current values
A4: Run | B4: Date/Time | C4: Temperature | D4: Rel. Temp. change | E4: RCS01 | F4: RCS02 | G4: RCS03 | H4: RCS04 | I4: RCS05 | J4: RCS06
C5: SOH:VAR6
B7: 45482.502 | E7: 0.466 | F7: 0.47 | G7: 0.484 | H7: 0.327 | I7: 0.611 | J7: 0.431
A8: Start | B8: 45484.569 | C8: 29.92 | D8: =C8-$C$8 -> 0 | E8: 0.417 | F8: 0.42 | G8: 0.433 | H8: 0.302 | I8: 0.556 | J8: 0.4
A9: 28263 | B9: 45484.78 | C9: 30.6 | D9: =C9-$C$8 -> 0.68 | E9: 0.427 | F9: 0.427 | G9: 0.434 | H9: 0.302 | I9: 0.565 | J9: 0.407
A10: 28264 | B10: 45484.831 | C10: 30.64 | D10: =C10-$C$8 -> 0.72 | E10: 0.439 | F10: 0.438 | G10: 0.445 | H10: 0.309 | I10: 0.577 | J10: 0.417
A11: 28266 | B11: 45484.863 | C11: 30.37 | D11: =C11-$C$8 -> 0.45 | E11: 0.445 | F11: 0.444 | G11: 0.451 | H11: 0.314 | I11: 0.584 | J11: 0.423
A12: 28267 | B12: 45484.908 | C12: 29.9 | D12: =C12-$C$8 -> -0.02 | E12: 0.452 | F12: 0.451 | G12: 0.459 | H12: 0.319 | I12: 0.592 | J12: 0.429
A13: 28268 | B13: 45484.947 | C13: 29.51 | D13: =C13-$C$8 -> -0.41 | E13: 0.456 | F13: 0.454 | G13: 0.463 | H13: 0.322 | I13: 0.595 | J13: 0.432
A14: 28269 | B14: 45484.988 | C14: 29.06 | D14: =C14-$C$8 -> -0.86 | E14: 0.453 | F14: 0.451 | G14: 0.462 | H14: 0.321 | I14: 0.591 | J14: 0.43
A15: 28270 | B15: 45485.03 | C15: 28.77 | D15: =C15-$C$8 -> -1.15 | E15: 0.447 | F15: 0.446 | G15: 0.457 | H15: 0.319 | I15: 0.584 | J15: 0.423
A16: 28271 | B16: 45485.061 | C16: 28.63 | D16: =C16-$C$8 -> -1.29 | E16: 0.442 | F16: 0.44 | G16: 0.452 | H16: 0.315 | I16: 0.577 | J16: 0.419
A17: 28272 | B17: 45485.105 | C17: 28.305 | D17: =C17-$C$8 -> -1.615 | E17: 0.435 | F17: 0.434 | G17: 0.445 | H17: 0.309 | I17: 0.568 | J17: 0.411
A18: 28273 | B18: 45485.146 | C18: 28.058 | D18: =C18-$C$8 -> -1.862 | E18: 0.427 | F18: 0.427 | G18: 0.439 | H18: 0.304 | I18: 0.559 | J18: 0.404
A19: 28274 | B19: 45485.187 | C19: 27.847 | D19: =C19-$C$8 -> -2.073 | E19: 0.42 | F19: 0.42 | G19: 0.431 | H19: 0.299 | I19: 0.549 | J19: 0.396
A20: 28275 | B20: 45485.228 | C20: 27.668 | D20: =C20-$C$8 -> -2.252 | E20: 0.409 | F20: 0.409 | G20: 0.42 | H20: 0.291 | I20: 0.535 | J20: 0.384
... A68: 28335 | B68: 45487.378 | C68: 28.634 | D68: =C68-$C$8 -> -1.286 | E68: 0.415 | F68: 0.414 | G68: 0.427 | H68: 0.295 | I68: 0.534 | J68: 0.385
A69: - | B69: 45487.435 | C69: 28.995 | D69: =C69-$C$8 -> -0.925 | E69: 0.41 | F69: 0.409 | G69: 0.42 | H69: 0.29 | I69: 0.527 | J69: 0.379
A70: 28337 | B70: 45487.469 | C70: 29.359 | D70: =C70-$C$8 -> -0.561 | E70: 0.41 | F70: 0.408 | G70: 0.419 | H70: 0.29 | I70: 0.527 | J70: 0.379
A71: 28343 | B71: 45487.528 | C71: 29.697 | D71: =C71-$C$8 -> -0.223 | E71: 0.416 | F71: 0.414 | G71: 0.425 | H71: 0.297 | I71: 0.534 | J71: 0.384
A72: 28345 | B72: 45487.596 | C72: 29.89 | D72: =C72-$C$8 -> -0.03 | E72: 0.42 | F72: 0.418 | G72: 0.429 | H72: 0.295 | I72: 0.54 | J72: 0.389
A73: 28348 | B73: 45487.634 | C73: 30.254 | D73: =C73-$C$8 -> 0.334 | E73: 0.425 | F73: 0.424 | G73: 0.435 | H73: 0.3 | I73: 0.549 | J73: 0.395
A74: 28351 | B74: 45487.676 | C74: 30.546 | D74: =C74-$C$8 -> 0.626 | E74: 0.429 | F74: 0.428 | G74: 0.44 | H74: 0.304 | I74: 0.556 | J74: 0.4
A75: End | B75: 45487.688 | C75: 30.667 | D75: =C75-$C$8 -> 0.747 | E75: 0.43 | F75: 0.429 | G75: 0.441 | H75: 0.304 | I75: 0.557 | J75: 0.402
A77: - | B77: 45489.662 | C77: 30.234 | E77: 0.435 | F77: 0.431 | G77: 0.449 | H77: 0.302 | I77: 0.576 | J77: 0.404

Sheet Calibrations
A1: HPGe and LaBr3 energy and efficiency calibration. Filter: All_singles.
B3: Pre-beam | H3: Post-beam
A4: Source | B4: ID | C4: Activity (𝝈) (kBq) | D4: Run time (hr) | E4: Run # | F4: Status | G4: Comments | H4: Run time (hrs) | I4: Run# | J4: Status | K4: Comments
A5: 60Co | B5: R1105 | C5: 38.18 | D5: 3 | E5: 28237 | F5: Done | H5: 3 | I5: 28358/28359 | J5: Done | K5: One BGO noisy at 28358, threshold increase at the middle of the run
A6: 152Eu | B6: R1103 | C6: 39.41 | D6: 3 | E6: 28243 | F6: Done | H6: 3 | I6: 28357 | J6: Done
A7: 56Co | B7: R1274 | C7: 300 | D7: 30 min | E7: 28238 | F7: Done | H7: 30min | I7: 28355 | J7: Done | K7: RCMP counts should be ignore
A8: 133Ba | B8: R0794 | C8: 38.78 | D8: 2 | E8: 28240 | F8: Done | H8: 2 | I8: 28362 | J8: Done
A9: 60Co | B9: R0793 | C9: 35 | D9: 1 | E9: 28239 | F9: Done | H9: 1 | I9: 28363 | J9: Done
A10: 244Cm/13C ->16O* (high energy gammas) | D10: 20 minutes | E10: 28254 | F10: Done | G10: 28246 is useful only for one hemisphere | H10: 15 | I10: 28378 | J10: Done | K10: West
A11: 244Cm/13C ->16O* (high energy gammas) | H11: 15 | I11: 28379 | J11: Done | K11: East
A12: Alpha Source calibration.Filter: All_singles.
B13: Pre-beam | H13: Post-beam
A14: Source | B14: ID | C14: Activity | D14: Run time (hr) | E14: Run # | F14: Status | G14: Comments | H14: Run time (hrs) | I14: Run# | J14: Status | K14: Comments
A15: 207Bi | B15: R00758 | C15: 40.7kBq | D15: 1 | E15: 28251, 28252 | F15: Done | G15: Vac safe source, pointing upstream, sig test | J15: not needed
A16: 3-alphax2sided | B16: 0968 A,B | C16: 11.10kBq | D16: 14 | E16: 28226 | F16: Done | G16: vertical position, RC01,02,05,06 iluminated | H16: 11 | I16: 28365 | J16: Done | K16: Vertical position
A17: 3-alphax2sided | B17: 0968 A,B | C17: 11.10kBq | D17: 9 | E17: 28241 | F17: Done | G17: vertical position, RC01,02,05,06 iluminated | H17: 1h 28m 44s | I17: 28367 | J17: Done | K17: Horizontal position | L17: Limited time using double sided alpha source, should be enough for calibration
A18: 3-alphax1sided + milar | D18: 1hour 25mins | E18: 28228 | F18: Done | G18: vertical position, RC01,02,05,06 iluminated | H18: 57 min | I18: 28377 | J18: Done
A19: 3-alphax1sided nomilar | D19: 22min 40sec | E19: 28227 | F19: Done | G19: vertical position, RC01,02,05,06 iluminated | H19: 8hr | I19: 28375 | J19: Done
D20: 1 | H20: 1 | I20: 28380 | J20: Done | K20: Mask on, RCS01,02
H21: 1 | I21: 28381 | J21: Done | K21: Mask on, RCS01506
H22: 1 | I22: 28382 | J22: Done | K22: Mask on, RCS03
A23: Fast-timing calibrations. Filter: Timing-calibration. ZDS on. HPGes on. | H23: 1 | I23: 28383 | J23: Done | K23: Mask on, RCS04
E25: Pre-beam | J25: Post-beam
A26: Source | B26: ID | C26: Activity | D26: Run time (hr) | E26: Run # | F26: Status | G26: Comments | H26: Run time (hrs) | I26: Run# | J26: Status | K26: Comments
A27: 152Eu | B27: R1195 | C27: 1.602 MBq | D27: 2 | E27: No time for these before the experiment | H27: 2 | I27: 28371 | J27: Done
A28: 60Co | B28: R1175 | C28: 1.924 MBq | D28: 2 | H28: 2 | I28: 28368 | J28: Done
A29: 207Bi | B29: R1197 | C29: 1.865 MBq | D29: 2 | H29: 1 | I29: 28373 | J29: Done
A30: 125Sb | B30: R1222 | C30: 1.5 MBq | D30: 2 | H30: 1 | I30: 27374 | J30: Done
A31: TAC Calibrator | D31: 15mins
A33: Gamma-gamma angular correlation calibration. Filter: Ge-Ge. ZDS off
D35: Post-beam
A36: Source | B36: ID | C36: Activity | D36: Run time (hrs) | E36: Run# | F36: Status | G36: Comments
A37: 152Eu | B37: R1195 | C37: 1.602 MBq | D37: 1 | E37: 28372 | F37: Done
A38: 60Co | B38: R1175 | C38: 1.924 MBq | D38: 1 | E38: 28370 | F38: Done
A41: Fast-timing calibrations. Filter: Timing-calibration. ZDS on. HPGes on. | F41: This calibrations were part of the S2189/S2319 experimental campagin. Prior to this beamtime, this ones should suffice
E43: Pre-beam
A44: Source | B44: ID | C44: Activity | D44: Run time (hr) | E44: Run # | F44: Status | G44: Comments
A45: 152Eu | B45: R1195 | C45: 1.602 MBq | D45: 2 | E45: 28165 | F45: Done | G45: located at /tig/grifstore1/grifalt/schedule146/Calibrations_June2024
A46: 60Co | B46: R1175 | C46: 1.924 MBq | D46: 2 | E46: 28169 | F46: Done
A47: 207Bi | B47: R1197 | C47: 1.865 MBq | D47: 3 | E47: 28168 | F47: Done
...

Sheet Efficiency
A1: 60Co (Run28237) | B1: Activity(38.18kBq+-3%) | C1: RunLength(10800s) | D1: NetEvents | E1: DeadTime(1us) | F1: Deadfraction | G1: Livefraction
A2: Additional Info. 60Co | B2: =38.18*1000 -> 38180 | C2: 10800 | D2: 122277700 | E2: 1e-06 | F2: =E2*(D2/C2) -> 0.011322009 | G2: =1-F2 -> 0.98867799 | H2: Checks
B3: ID | C3: Activity | D3: Manuf. Date | E3: Expe. Date | F3: Delta t (days) | G3: T_1/2day | H3: T_1/2Uncertainty | I3: Lambda | J3: A[kBq] | K3: A[Bq] | L3: Uncertainty
A4: 60Co | B4: R1105 | C4: 38.18 | D4: 42491 | E4: 45482 | F4: =E4-D4 -> 2991 | G4: 1925.28 | H4: 14 | I4: =LN(2)/G4 -> 0.00036002409 | J4: =C4*EXP(-I4*F4) -> 13.006897 | K4: =1000*J4 -> 13006.897 | L4: =0.01*C4 -> 0.3818
A5: Energies (keV) | B5: Area | C5: Uncer-Area | D5: Intensity | E5: Uncer-intensity | F5: Efficiency | G5: Uncer-Effiency | H5: with Deadfraction
A6: 1173.228 | B6: 7858480 | C6: 3719.46 | D6: 0.9985 | E6: 0.0003 | F6: =(((B6/(D6*$K$4*($C$2-$E$2*$D$2))))) -> 0.056668035 | G6: =F6*SQRT((C6/B6)^2+(E6/D6)^2) -> 3.1768916e-05 | H6: =B6/(D6*$B$2*($C$2-$F$2)) -> 0.019086718 | I6: =H6*SQRT((C6/B6)^2+(E6/D6)^2) -> 1.0700289e-05
A7: 1332.492 | B7: 7355880 | C7: 5768.14 | D7: 0.999826 | E7: 0.0006 | F7: =(((B7/(D7*$K$4*($C$2-$E$2*$D$2))))) -> 0.052973404 | G7: =F7*SQRT((C7/B7)^2+(E7/D7)^2) -> 5.2307642e-05 | H7: =B7/(D7*$B$2*($C$2-$F$2)) -> 0.017842306 | I7: =H7*SQRT((C7/B7)^2+(E7/D7)^2) -> 1.7618066e-05
A9: 152Eu (Run28243) - To be Scale with 60Co
A10: Energies (keV) | B10: Area | C10: Uncer-Area | D10: Intensity | E10: Uncer-intensity | F10: Efficiency | G10: Uncer-Effiency
A11: 121.7817 | B11: 16166000 | C11: 17180.6 | D11: 1.073 | E11: 0.0003 | F11: =(((B11/D11))) -> 15066170 | G11: =F11*SQRT((C11/B11)^2+(E11/D11)^2) -> 16556.563
A12: 244.6974 | B12: 3443590 | C12: 29221.7 | D12: 0.2839 | E12: 0.001 | F12: =(((B12/D12))) -> 12129588 | G12: =F12*SQRT((C12/B12)^2+(E12/D12)^2) -> 111444.63
A13: 295.9387 | B13: 176268 | C13: 9314.68 | D13: 0.01656 | E13: 0.0015 | F13: =(((B13/D13))) -> 10644203 | G13: =F13*SQRT((C13/B13)^2+(E13/D13)^2) -> 1116229.1
A14: 344.2785 | B14: 9832300 | C14: 9868.89 | D14: 1 | E14: 0.0006 | F14: =(((B14/D14))) -> 9832300 | G14: =F14*SQRT((C14/B14)^2+(E14/D14)^2) -> 11497.725
A15: 367.7891 | B15: 310037 | C15: 1239.1 | D15: 0.03232 | E15: 0.0015 | F15: =(((B15/D15))) -> 9592729 | G15: =F15*SQRT((C15/B15)^2+(E15/D15)^2) -> 446854.79
A16: 411.1165 | B16: 708569 | C16: 17959 | D16: 0.08413 | E16: 0.0026 | F16: =(((B16/D16))) -> 8422310.7 | G16: =F16*SQRT((C16/B16)^2+(E16/D16)^2) -> 336627.36
A17: 443.9606 | B17: 976153 | C17: 5122.45 | D17: 0.1063 | E17: 0.0003 | F17: =(((B17/D17))) -> 9183000.9 | G17: =F17*SQRT((C17/B17)^2+(E17/D17)^2) -> 54715.594
A18: 488.6792 | B18: 115319 | C18: 1162.28 | D18: 0.01558 | E18: 0.001 | F18: =(((B18/D18))) -> 7401733 | G18: =F18*SQRT((C18/B18)^2+(E18/D18)^2) -> 480900.68
A19: 586.2648 | B19: 120113 | C19: 1595.16 | D19: 0.0171 | E19: 0.0013 | F19: =(((B19/D19))) -> 7024152 | G19: =F19*SQRT((C19/B19)^2+(E19/D19)^2) -> 542086.52
A20: 678.623 | B20: 175615 | C20: 1624.52 | D20: 0.01777 | E20: 0.0012 | F20: =(((B20/D20))) -> 9882667.4 | G20: =F20*SQRT((C20/B20)^2+(E20/D20)^2) -> 673604.41
A21: 688.67 | B21: 202009 | C21: 4017.37 | D21: 0.03221 | E21: 0.0019 | F21: =(((B21/D21))) -> 6271623.7 | G21: =F21*SQRT((C21/B21)^2+(E21/D21)^2) -> 390408.83
A22: 778.9045 | B22: 2911740 | C22: 6272.43 | D22: 0.4862 | E22: 0.0022 | F22: =(((B22/D22))) -> 5988770.1 | G22: =F22*SQRT((C22/B22)^2+(E22/D22)^2) -> 30012.713
... A30: 1408.013 | B30: 3346920 | C30: 1943.38 | D30: 0.7848 | E30: 0.0013 | F30: =(((B30/D30))) -> 4264678.9 | G30: =F30*SQRT((C30/B30)^2+(E30/D30)^2) -> 7485.7616
A32: 56Co (Run28238) -To be Scale with 60Co
A33: Energies (keV) | B33: Area | C33: Uncer-Area | D33: Intensity | E33: Uncer-intensity | F33: Efficiency | G33: Uncer-Effiency
A34: 846.77 | B34: 9380000 | C34: 6766.26 | D34: 1 | E34: 0 | F34: =(((B34/D34))) -> 9380000 | G34: =F34*SQRT((C34/B34)^2+(E34/D34)^2) -> 6766.26
A35: 1037.843 | B35: 1170000 | C35: 1302.87 | D35: 0.1406 | E35: 0.0004 | F35: =(((B35/D35))) -> 8321479.4 | G35: =F35*SQRT((C35/B35)^2+(E35/D35)^2) -> 25423.13
A36: 1175.101 | B36: 174939 | C36: 1154.59 | D36: 0.02253 | E36: 0.0006 | F36: =(((B36/D36))) -> 7764713.7 | G36: =F36*SQRT((C36/B36)^2+(E36/D36)^2) -> 213038.9
A37: 1238.288 | B37: 5030000 | C37: 2386.57 | D37: 0.665 | E37: 0.0012 | F37: =(((B37/D37))) -> 7563909.8 | G37: =F37*SQRT((C37/B37)^2+(E37/D37)^2) -> 14113.088
A38: 1360.212 | B38: 311166 | C38: 790.991 | D38: 0.04286 | E38: 0.0012 | F38: =(((B38/D38))) -> 7260056 | G38: =F38*SQRT((C38/B38)^2+(E38/D38)^2) -> 204104.1
A39: 1771.357 | B39: 927802 | C39: 1133.32 | D39: 0.1542 | E39: 0.0006 | F39: =(((B39/D39))) -> 6016874.2 | G39: =F39*SQRT((C39/B39)^2+(E39/D39)^2) -> 24538.494
A40: 2015.215 | B40: 164902 | C40: 692.442 | D40: 0.03018 | E40: 0.0012 | F40: =(((B40/D40))) -> 5463949.6 | G40: =F40*SQRT((C40/B40)^2+(E40/D40)^2) -> 218462.62
A41: 2034.791 | B41: 426827 | C41: 759.129 | D41: 0.07774 | E41: 0.0028 | F41: =(((B41/D41))) -> 5490442.5 | G41: =F41*SQRT((C41/B41)^2+(E41/D41)^2) -> 197992.93
A42: 2598.5 | B42: 766027 | C42: 927.945 | D42: 0.1698 | E42: 0.0004 | F42: =(((B42/D42))) -> 4511348.6 | G42: =F42*SQRT((C42/B42)^2+(E42/D42)^2) -> 11950.228
A43: 3009.645 | B43: 41900 | C43: 848.574 | D43: 0.01037 | E43: 0.0013 | F43: =(((B43/D43))) -> 4040501.4 | G43: =F43*SQRT((C43/B43)^2+(E43/D43)^2) -> 513091.09
A44: 3202.029 | B44: 118048 | C44: 370.414 | D44: 0.03211 | E44: 0.0012 | F44: =(((B44/D44))) -> 3676362.5 | G44: =F44*SQRT((C44/B44)^2+(E44/D44)^2) -> 137874.75
A45: 3253.503 | B45: 287339 | C45: 583.523 | D45: 0.07928 | E45: 0.0021 | F45: =(((B45/D45))) -> 3624356.7 | G45: =F45*SQRT((C45/B45)^2+(E45/D45)^2) -> 96285.126
... A47: 3451.232 | B47: 33417.4 | C47: 197.597 | D47: 0.0095 | E47: 0.0005 | F47: =(((B47/D47))) -> 3517621.1 | G47: =F47*SQRT((C47/B47)^2+(E47/D47)^2) -> 186302.68
A71: Adding the lower energies
A72: 133Ba (Run28240) -To be Scale with 60Co
A73: Energies (keV) | B73: Area | C73: Uncer-Area | D73: Intensity | E73: Uncer-intensity | F73: Efficiency | G73: Uncer-Effiency
...

Sheet Magnet tune
D9: magnets value | E9: 20Na/20Mg
D10: -1245.7 | E10: 1.294
D11: -1245.3
D12: -1250

Sheet Rate_calculator
A1: Only edit the cells coloured YELLOW and "nothing else" | E1: Created by Dhruval
A2: Note: All decimal places are not shown but are included in calculations
A4: Rate (ions/s)
A5: R_34Ar | B5: 150000
A6: R_34Cl | B6: 10000
A7: R_34Cl_m | B7: 10000000
A8: R_X | B8: 0
A10: Half-life (s) | B10: Ref: NNDC
A11: t_34Ar | B11: 0.8445
A12: t_34Cl | B12: 1.5264
A13: t_34Cl_m | B13: =32*60 -> 1920
A14: t_X | B14: 2.511
A16: Decay const. (1/s)
A17: λ_34Ar | B17: =LN(2)/B11 -> 0.82077819
A18: λ_34Cl | B18: =LN(2)/B12 -> 0.45410586
A19: λ_34Cl_m | B19: =LN(2)/B13 -> 0.00036101416
A20: λ_X | B20: =LN(2)/B14 -> 0.27604428
A22: Beam ON, T (s) | B22: 2
A23: Beam OFF (s) | B23: 20
A24: # of steps | B24: 500
A26: BG offset (c/s) | B26: 50
A88: Intermediate terms
A89: exp(λ_Ar*T) | B89: =EXP(B17*$B$22) -> 5.1631992
A90: exp(λ_Cl*T) | B90: =EXP(B18*$B$22) -> 2.4798838
A91: exp(λ_Cl_m*T) | B91: =EXP(B19*$B$22) -> 1.0007223
A92: exp(λ_My*T) | B92: =EXP(B20*$B$22) -> 1.7368768
A93: λ_Cl - λ_Ar | B93: =B18-B17 -> -0.36667233

Sheet Calculations_DO_NOT_EDIT
A1: Note: All decimal places are not shown but are included in calculations
A3: Time, t (s) | B3: A_Ar (Bq) | C3: A_Cl (Bq) | D3: A_Cl_m (Bq) | E3: A_X (Bq) | F3: A_total (Bq) | G3: BG | I3: exp(-λ_Ar*t) | J3: exp(-λ_Cl*t) | K3: exp(-λ_Cl_m*t) | L3: exp(-λ_X*t) | M3: exp(-λ_Cl*t) - exp(-λ_Ar*t)
A4: 1e-05 | B4: =IF(A4<=Rate_calculator!$B$22, Rate_calculator!$B$5*(1-I4), Rate_calculator!$B$5*I4*(Rate_calculator!$B$89-1)) -> 1.2311622 | C4: =IF(A4<=Rate_calculator!$B$22, (Rate_calculator!$B$5+Rate_calculator!$B$6)*(1-J4)+Rate_calculator!$B$5*Rate_calculator!$B$18/Rate_calculator!$B$93*M4, (Rate_calculator!$B$5*Rate_calculator!$B$18*I4*(Rate_calculator!$B$89-1)/Rate_calculator!$B$93)+(Rate_calculator!$B$5*J4*(Rate_calculator!$B$90+Rate_calculator!$B$18/Rate_calculator!$B$93-Rate_calculator!$B$18*Rate_calculator!$B$90/Rate_calculator!$B$93-1))+(Rate_calculator!$B$6*J4*(Rate_calculator!$B$90-1))) -> 0.045413278 | D4: =IF(A4<=Rate_calculator!$B$22, Rate_calculator!$B$7*(1-K4), Rate_calculator!$B$7*K4*(Rate_calculator!$B$91-1)) -> 0.036101415 | E4: =IF(A4<=Rate_calculator!$B$22, Rate_calculator!$B$8*(1-L4), (Rate_calculator!$B$8*L4*(Rate_calculator!$B$92-1))) -> 0 | F4: =B4+C4+D4+E4+Rate_calculator!$B$26 -> 51.312677 | G4: =Rate_calculator!$B$26 -> 50 | I4: =EXP(-Rate_calculator!$B$17*A4) -> 0.99999179 | J4: =EXP(-Rate_calculator!$B$18*A4) -> 0.99999546 | K4: =EXP(-Rate_calculator!$B$19*A4) -> 1 | L4: =EXP(-Rate_calculator!$B$20*A4) -> 0.99999724 | M4: =J4-I4 -> 3.6666999e-06
A5: =A4+(Rate_calculator!$B$22+Rate_calculator!$B$23)/Rate_calculator!$B$24 -> 0.04401 | B5: =IF(A5<=Rate_calculator!$B$22, Rate_calculator!$B$5*(1-I5), Rate_calculator!$B$5*I5*(Rate_calculator!$B$89-1)) -> 5321.6726 | C5: =IF(A5<=Rate_calculator!$B$22, (Rate_calculator!$B$5+Rate_calculator!$B$6)*(1-J5)+Rate_calculator!$B$5*Rate_calculator!$B$18/Rate_calculator!$B$93*M5, (Rate_calculator!$B$5*Rate_calculator!$B$18*I5*(Rate_calculator!$B$89-1)/Rate_calculator!$B$93)+(Rate_calculator!$B$5*J5*(Rate_calculator!$B$90+Rate_calculator!$B$18/Rate_calculator!$B$93-Rate_calculator!$B$18*Rate_calculator!$B$90/Rate_calculator!$B$93-1))+(Rate_calculator!$B$6*J5*(Rate_calculator!$B$90-1))) -> 251.01 | D5: =IF(A5<=Rate_calculator!$B$22, Rate_calculator!$B$7*(1-K5), Rate_calculator!$B$7*K5*(Rate_calculator!$B$91-1)) -> 158.88107 | E5: =IF(A5<=Rate_calculator!$B$22, Rate_calculator!$B$8*(1-L5), (Rate_calculator!$B$8*L5*(Rate_calculator!$B$92-1))) -> 0 | F5: =B5+C5+D5+E5+Rate_calculator!$B$26 -> 5781.5637 | G5: =Rate_calculator!$B$26 -> 50 | I5: =EXP(-Rate_calculator!$B$17*A5) -> 0.96452218 | J5: =EXP(-Rate_calculator!$B$18*A5) -> 0.98021318 | K5: =EXP(-Rate_calculator!$B$19*A5) -> 0.99998411 | L5: =EXP(-Rate_calculator!$B$20*A5) -> 0.98792479 | M5: =J5-I5 -> 0.015690999
A6: =A5+(Rate_calculator!$B$22+Rate_calculator!$B$23)/Rate_calculator!$B$24 -> 0.08801 | B6: =IF(A6<=Rate_calculator!$B$22, Rate_calculator!$B$5*(1-I6), Rate_calculator!$B$5*I6*(Rate_calculator!$B$89-1)) -> 10453.399 | C6: =IF(A6<=Rate_calculator!$B$22, (Rate_calculator!$B$5+Rate_calculator!$B$6)*(1-J6)+Rate_calculator!$B$5*Rate_calculator!$B$18/Rate_calculator!$B$93*M6, (Rate_calculator!$B$5*Rate_calculator!$B$18*I6*(Rate_calculator!$B$89-1)/Rate_calculator!$B$93)+(Rate_calculator!$B$5*J6*(Rate_calculator!$B$90+Rate_calculator!$B$18/Rate_calculator!$B$93-Rate_calculator!$B$18*Rate_calculator!$B$90/Rate_calculator!$B$93-1))+(Rate_calculator!$B$6*J6*(Rate_calculator!$B$90-1))) -> 600.37676 | D6: =IF(A6<=Rate_calculator!$B$22, Rate_calculator!$B$7*(1-K6), Rate_calculator!$B$7*K6*(Rate_calculator!$B$91-1)) -> 317.72351 | E6: =IF(A6<=Rate_calculator!$B$22, Rate_calculator!$B$8*(1-L6), (Rate_calculator!$B$8*L6*(Rate_calculator!$B$92-1))) -> 0 | F6: =B6+C6+D6+E6+Rate_calculator!$B$26 -> 11421.499 | G6: =Rate_calculator!$B$26 -> 50 | I6: =EXP(-Rate_calculator!$B$17*A6) -> 0.93031068 | J6: =EXP(-Rate_calculator!$B$18*A6) -> 0.96082224 | K6: =EXP(-Rate_calculator!$B$19*A6) -> 0.99996823 | L6: =EXP(-Rate_calculator!$B$20*A6) -> 0.97599808 | M6: =J6-I6 -> 0.030511568
A7: =A6+(Rate_calculator!$B$22+Rate_calculator!$B$23)/Rate_calculator!$B$24 -> 0.13201 | B7: =IF(A7<=Rate_calculator!$B$22, Rate_calculator!$B$5*(1-I7), Rate_calculator!$B$5*I7*(Rate_calculator!$B$89-1)) -> 15403.103 | C7: =IF(A7<=Rate_calculator!$B$22, (Rate_calculator!$B$5+Rate_calculator!$B$6)*(1-J7)+Rate_calculator!$B$5*Rate_calculator!$B$18/Rate_calculator!$B$93*M7, (Rate_calculator!$B$5*Rate_calculator!$B$18*I7*(Rate_calculator!$B$89-1)/Rate_calculator!$B$93)+(Rate_calculator!$B$5*J7*(Rate_calculator!$B$90+Rate_calculator!$B$18/Rate_calculator!$B$93-Rate_calculator!$B$18*Rate_calculator!$B$90/Rate_calculator!$B$93-1))+(Rate_calculator!$B$6*J7*(Rate_calculator!$B$90-1))) -> 1042.5327 | D7: =IF(A7<=Rate_calculator!$B$22, Rate_calculator!$B$7*(1-K7), Rate_calculator!$B$7*K7*(Rate_calculator!$B$91-1)) -> 476.56343 | E7: =IF(A7<=Rate_calculator!$B$22, Rate_calculator!$B$8*(1-L7), (Rate_calculator!$B$8*L7*(Rate_calculator!$B$92-1))) -> 0 | F7: =B7+C7+D7+E7+Rate_calculator!$B$26 -> 16972.199 | G7: =Rate_calculator!$B$26 -> 50 | I7: =EXP(-Rate_calculator!$B$17*A7) -> 0.89731265 | J7: =EXP(-Rate_calculator!$B$18*A7) -> 0.94181491 | K7: =EXP(-Rate_calculator!$B$19*A7) -> 0.99995234 | L7: =EXP(-Rate_calculator!$B$20*A7) -> 0.96421536 | M7: =J7-I7 -> 0.044502258
A8: =A7+(Rate_calculator!$B$22+Rate_calculator!$B$23)/Rate_calculator!$B$24 -> 0.17601 | B8: =IF(A8<=Rate_calculator!$B$22, Rate_calculator!$B$5*(1-I8), Rate_calculator!$B$5*I8*(Rate_calculator!$B$89-1)) -> 20177.241 | C8: =IF(A8<=Rate_calculator!$B$22, (Rate_calculator!$B$5+Rate_calculator!$B$6)*(1-J8)+Rate_calculator!$B$5*Rate_calculator!$B$18/Rate_calculator!$B$93*M8, (Rate_calculator!$B$5*Rate_calculator!$B$18*I8*(Rate_calculator!$B$89-1)/Rate_calculator!$B$93)+(Rate_calculator!$B$5*J8*(Rate_calculator!$B$90+Rate_calculator!$B$18/Rate_calculator!$B$93-Rate_calculator!$B$18*Rate_calculator!$B$90/Rate_calculator!$B$93-1))+(Rate_calculator!$B$6*J8*(Rate_calculator!$B$90-1))) -> 1572.1058 | D8: =IF(A8<=Rate_calculator!$B$22, Rate_calculator!$B$7*(1-K8), Rate_calculator!$B$7*K8*(Rate_calculator!$B$91-1)) -> 635.40083 | E8: =IF(A8<=Rate_calculator!$B$22, Rate_calculator!$B$8*(1-L8), (Rate_calculator!$B$8*L8*(Rate_calculator!$B$92-1))) -> 0 | F8: =B8+C8+D8+E8+Rate_calculator!$B$26 -> 22434.748 | G8: =Rate_calculator!$B$26 -> 50 | I8: =EXP(-Rate_calculator!$B$17*A8) -> 0.86548506 | J8: =EXP(-Rate_calculator!$B$18*A8) -> 0.92318358 | K8: =EXP(-Rate_calculator!$B$19*A8) -> 0.99993646 | L8: =EXP(-Rate_calculator!$B$20*A8) -> 0.95257489 | M8: =J8-I8 -> 0.05769852
A9: =A8+(Rate_calculator!$B$22+Rate_calculator!$B$23)/Rate_calculator!$B$24 -> 0.22001 | B9: =IF(A9<=Rate_calculator!$B$22, Rate_calculator!$B$5*(1-I9), Rate_calculator!$B$5*I9*(Rate_calculator!$B$89-1)) -> 24782.042 | C9: =IF(A9<=Rate_calculator!$B$22, (Rate_calculator!$B$5+Rate_calculator!$B$6)*(1-J9)+Rate_calculator!$B$5*Rate_calculator!$B$18/Rate_calculator!$B$93*M9, (Rate_calculator!$B$5*Rate_calculator!$B$18*I9*(Rate_calculator!$B$89-1)/Rate_calculator!$B$93)+(Rate_calculator!$B$5*J9*(Rate_calculator!$B$90+Rate_calculator!$B$18/Rate_calculator!$B$93-Rate_calculator!$B$18*Rate_calculator!$B$90/Rate_calculator!$B$93-1))+(Rate_calculator!$B$6*J9*(Rate_calculator!$B$90-1))) -> 2183.9558 | D9: =IF(A9<=Rate_calculator!$B$22, Rate_calculator!$B$7*(1-K9), Rate_calculator!$B$7*K9*(Rate_calculator!$B$91-1)) -> 794.2357 | E9: =IF(A9<=Rate_calculator!$B$22, Rate_calculator!$B$8*(1-L9), (Rate_calculator!$B$8*L9*(Rate_calculator!$B$92-1))) -> 0 | F9: =B9+C9+D9+E9+Rate_calculator!$B$26 -> 27810.233 | G9: =Rate_calculator!$B$26 -> 50 | I9: =EXP(-Rate_calculator!$B$17*A9) -> 0.83478639 | J9: =EXP(-Rate_calculator!$B$18*A9) -> 0.90492082 | K9: =EXP(-Rate_calculator!$B$19*A9) -> 0.99992058 | L9: =EXP(-Rate_calculator!$B$20*A9) -> 0.94107494 | M9: =J9-I9 -> 0.070134433
A10: =A9+(Rate_calculator!$B$22+Rate_calculator!$B$23)/Rate_calculator!$B$24 -> 0.26401 | B10: =IF(A10<=Rate_calculator!$B$22, Rate_calculator!$B$5*(1-I10), Rate_calculator!$B$5*I10*(Rate_calculator!$B$89-1)) -> 29223.51 | C10: =IF(A10<=Rate_calculator!$B$22, (Rate_calculator!$B$5+Rate_calculator!$B$6)*(1-J10)+Rate_calculator!$B$5*Rate_calculator!$B$18/Rate_calculator!$B$93*M10, (Rate_calculator!$B$5*Rate_calculator!$B$18*I10*(Rate_calculator!$B$89-1)/Rate_calculator!$B$93)+(Rate_calculator!$B$5*J10*(Rate_calculator!$B$90+Rate_calculator!$B$18/Rate_calculator!$B$93-Rate_calculator!$B$18*Rate_calculator!$B$90/Rate_calculator!$B$93-1))+(Rate_calculator!$B$6*J10*(Rate_calculator!$B$90-1))) -> 2873.1652 | D10: =IF(A10<=Rate_calculator!$B$22, Rate_calculator!$B$7*(1-K10), Rate_calculator!$B$7*K10*(Rate_calculator!$B$91-1)) -> 953.06805 | E10: =IF(A10<=Rate_calculator!$B$22, Rate_calculator!$B$8*(1-L10), (Rate_calculator!$B$8*L10*(Rate_calculator!$B$92-1))) -> 0 | F10: =B10+C10+D10+E10+Rate_calculator!$B$26 -> 33099.744 | G10: =Rate_calculator!$B$26 -> 50 | I10: =EXP(-Rate_calculator!$B$17*A10) -> 0.8051766 | J10: =EXP(-Rate_calculator!$B$18*A10) -> 0.88701935 | K10: =EXP(-Rate_calculator!$B$19*A10) -> 0.99990469 | L10: =EXP(-Rate_calculator!$B$20*A10) -> 0.92971383 | M10: =J10-I10 -> 0.081842747
A11: =A10+(Rate_calculator!$B$22+Rate_calculator!$B$23)/Rate_calculator!$B$24 -> 0.30801 | B11: =IF(A11<=Rate_calculator!$B$22, Rate_calculator!$B$5*(1-I11), Rate_calculator!$B$5*I11*(Rate_calculator!$B$89-1)) -> 33507.44 | C11: =IF(A11<=Rate_calculator!$B$22, (Rate_calculator!$B$5+Rate_calculator!$B$6)*(1-J11)+Rate_calculator!$B$5*Rate_calculator!$B$18/Rate_calculator!$B$93*M11, (Rate_calculator!$B$5*Rate_calculator!$B$18*I11*(Rate_calculator!$B$89-1)/Rate_calculator!$B$93)+(Rate_calculator!$B$5*J11*(Rate_calculator!$B$90+Rate_calculator!$B$18/Rate_calculator!$B$93-Rate_calculator!$B$18*Rate_calculator!$B$90/Rate_calculator!$B$93-1))+(Rate_calculator!$B$6*J11*(Rate_calculator!$B$90-1))) -> 3635.0304 | D11: =IF(A11<=Rate_calculator!$B$22, Rate_calculator!$B$7*(1-K11), Rate_calculator!$B$7*K11*(Rate_calculator!$B$91-1)) -> 1111.8979 | E11: =IF(A11<=Rate_calculator!$B$22, Rate_calculator!$B$8*(1-L11), (Rate_calculator!$B$8*L11*(Rate_calculator!$B$92-1))) -> 0 | F11: =B11+C11+D11+E11+Rate_calculator!$B$26 -> 38304.369 | G11: =Rate_calculator!$B$26 -> 50 | I11: =EXP(-Rate_calculator!$B$17*A11) -> 0.77661706 | J11: =EXP(-Rate_calculator!$B$18*A11) -> 0.869472 | K11: =EXP(-Rate_calculator!$B$19*A11) -> 0.99988881 | L11: =EXP(-Rate_calculator!$B$20*A11) -> 0.91848987 | M11: =J11-I11 -> 0.092854939
A12: =A11+(Rate_calculator!$B$22+Rate_calculator!$B$23)/Rate_calculator!$B$24 -> 0.35201 | B12: =IF(A12<=Rate_calculator!$B$22, Rate_calculator!$B$5*(1-I12), Rate_calculator!$B$5*I12*(Rate_calculator!$B$89-1)) -> 37639.42 | C12: =IF(A12<=Rate_calculator!$B$22, (Rate_calculator!$B$5+Rate_calculator!$B$6)*(1-J12)+Rate_calculator!$B$5*Rate_calculator!$B$18/Rate_calculator!$B$93*M12, (Rate_calculator!$B$5*Rate_calculator!$B$18*I12*(Rate_calculator!$B$89-1)/Rate_calculator!$B$93)+(Rate_calculator!$B$5*J12*(Rate_calculator!$B$90+Rate_calculator!$B$18/Rate_calculator!$B$93-Rate_calculator!$B$18*Rate_calculator!$B$90/Rate_calculator!$B$93-1))+(Rate_calculator!$B$6*J12*(Rate_calculator!$B$90-1))) -> 4465.0533 | D12: =IF(A12<=Rate_calculator!$B$22, Rate_calculator!$B$7*(1-K12), Rate_calculator!$B$7*K12*(Rate_calculator!$B$91-1)) -> 1270.7252 | E12: =IF(A12<=Rate_calculator!$B$22, Rate_calculator!$B$8*(1-L12), (Rate_calculator!$B$8*L12*(Rate_calculator!$B$92-1))) -> 0 | F12: =B12+C12+D12+E12+Rate_calculator!$B$26 -> 43425.199 | G12: =Rate_calculator!$B$26 -> 50 | I12: =EXP(-Rate_calculator!$B$17*A12) -> 0.74907053 | J12: =EXP(-Rate_calculator!$B$18*A12) -> 0.85227179 | K12: =EXP(-Rate_calculator!$B$19*A12) -> 0.99987293 | L12: =EXP(-Rate_calculator!$B$20*A12) -> 0.90740142 | M12: =J12-I12 -> 0.10320126
A13: =A12+(Rate_calculator!$B$22+Rate_calculator!$B$23)/Rate_calculator!$B$24 -> 0.39601 | B13: =IF(A13<=Rate_calculator!$B$22, Rate_calculator!$B$5*(1-I13), Rate_calculator!$B$5*I13*(Rate_calculator!$B$89-1)) -> 41624.839 | C13: =IF(A13<=Rate_calculator!$B$22, (Rate_calculator!$B$5+Rate_calculator!$B$6)*(1-J13)+Rate_calculator!$B$5*Rate_calculator!$B$18/Rate_calculator!$B$93*M13, (Rate_calculator!$B$5*Rate_calculator!$B$18*I13*(Rate_calculator!$B$89-1)/Rate_calculator!$B$93)+(Rate_calculator!$B$5*J13*(Rate_calculator!$B$90+Rate_calculator!$B$18/Rate_calculator!$B$93-Rate_calculator!$B$18*Rate_calculator!$B$90/Rate_calculator!$B$93-1))+(Rate_calculator!$B$6*J13*(Rate_calculator!$B$90-1))) -> 5358.9335 | D13: =IF(A13<=Rate_calculator!$B$22, Rate_calculator!$B$7*(1-K13), Rate_calculator!$B$7*K13*(Rate_calculator!$B$91-1)) -> 1429.55 | E13: =IF(A13<=Rate_calculator!$B$22, Rate_calculator!$B$8*(1-L13), (Rate_calculator!$B$8*L13*(Rate_calculator!$B$92-1))) -> 0 | F13: =B13+C13+D13+E13+Rate_calculator!$B$26 -> 48463.322 | G13: =Rate_calculator!$B$26 -> 50 | I13: =EXP(-Rate_calculator!$B$17*A13) -> 0.72250108 | J13: =EXP(-Rate_calculator!$B$18*A13) -> 0.83541183 | K13: =EXP(-Rate_calculator!$B$19*A13) -> 0.99985705 | L13: =EXP(-Rate_calculator!$B$20*A13) -> 0.89644683 | M13: =J13-I13 -> 0.11291076
A14: =A13+(Rate_calculator!$B$22+Rate_calculator!$B$23)/Rate_calculator!$B$24 -> 0.44001 | B14: =IF(A14<=Rate_calculator!$B$22, Rate_calculator!$B$5*(1-I14), Rate_calculator!$B$5*I14*(Rate_calculator!$B$89-1)) -> 45468.895 | C14: =IF(A14<=Rate_calculator!$B$22, (Rate_calculator!$B$5+Rate_calculator!$B$6)*(1-J14)+Rate_calculator!$B$5*Rate_calculator!$B$18/Rate_calculator!$B$93*M14, (Rate_calculator!$B$5*Rate_calculator!$B$18*I14*(Rate_calculator!$B$89-1)/Rate_calculator!$B$93)+(Rate_calculator!$B$5*J14*(Rate_calculator!$B$90+Rate_calculator!$B$18/Rate_calculator!$B$93-Rate_calculator!$B$18*Rate_calculator!$B$90/Rate_calculator!$B$93-1))+(Rate_calculator!$B$6*J14*(Rate_calculator!$B$90-1))) -> 6312.5604 | D14: =IF(A14<=Rate_calculator!$B$22, Rate_calculator!$B$7*(1-K14), Rate_calculator!$B$7*K14*(Rate_calculator!$B$91-1)) -> 1588.3722 | E14: =IF(A14<=Rate_calculator!$B$22, Rate_calculator!$B$8*(1-L14), (Rate_calculator!$B$8*L14*(Rate_calculator!$B$92-1))) -> 0 | F14: =B14+C14+D14+E14+Rate_calculator!$B$26 -> 53419.828 | G14: =Rate_calculator!$B$26 -> 50 | I14: =EXP(-Rate_calculator!$B$17*A14) -> 0.69687403 | J14: =EXP(-Rate_calculator!$B$18*A14) -> 0.81888541 | K14: =EXP(-Rate_calculator!$B$19*A14) -> 0.99984116 | L14: =EXP(-Rate_calculator!$B$20*A14) -> 0.88562449 | M14: =J14-I14 -> 0.12201138
A15: =A14+(Rate_calculator!$B$22+Rate_calculator!$B$23)/Rate_calculator!$B$24 -> 0.48401 | B15: =IF(A15<=Rate_calculator!$B$22, Rate_calculator!$B$5*(1-I15), Rate_calculator!$B$5*I15*(Rate_calculator!$B$89-1)) -> 49176.603 | C15: =IF(A15<=Rate_calculator!$B$22, (Rate_calculator!$B$5+Rate_calculator!$B$6)*(1-J15)+Rate_calculator!$B$5*Rate_calculator!$B$18/Rate_calculator!$B$93*M15, (Rate_calculator!$B$5*Rate_calculator!$B$18*I15*(Rate_calculator!$B$89-1)/Rate_calculator!$B$93)+(Rate_calculator!$B$5*J15*(Rate_calculator!$B$90+Rate_calculator!$B$18/Rate_calculator!$B$93-Rate_calculator!$B$18*Rate_calculator!$B$90/Rate_calculator!$B$93-1))+(Rate_calculator!$B$6*J15*(Rate_calculator!$B$90-1))) -> 7322.0055 | D15: =IF(A15<=Rate_calculator!$B$22, Rate_calculator!$B$7*(1-K15), Rate_calculator!$B$7*K15*(Rate_calculator!$B$91-1)) -> 1747.192 | E15: =IF(A15<=Rate_calculator!$B$22, Rate_calculator!$B$8*(1-L15), (Rate_calculator!$B$8*L15*(Rate_calculator!$B$92-1))) -> 0 | F15: =B15+C15+D15+E15+Rate_calculator!$B$26 -> 58295.8 | G15: =Rate_calculator!$B$26 -> 50 | I15: =EXP(-Rate_calculator!$B$17*A15) -> 0.67215598 | J15: =EXP(-Rate_calculator!$B$18*A15) -> 0.80268592 | K15: =EXP(-Rate_calculator!$B$19*A15) -> 0.99982528 | L15: =EXP(-Rate_calculator!$B$20*A15) -> 0.8749328 | M15: =J15-I15 -> 0.13052994
A16: =A15+(Rate_calculator!$B$22+Rate_calculator!$B$23)/Rate_calculator!$B$24 -> 0.52801 | B16: =IF(A16<=Rate_calculator!$B$22, Rate_calculator!$B$5*(1-I16), Rate_calculator!$B$5*I16*(Rate_calculator!$B$89-1)) -> 52752.799 | C16: =IF(A16<=Rate_calculator!$B$22, (Rate_calculator!$B$5+Rate_calculator!$B$6)*(1-J16)+Rate_calculator!$B$5*Rate_calculator!$B$18/Rate_calculator!$B$93*M16, (Rate_calculator!$B$5*Rate_calculator!$B$18*I16*(Rate_calculator!$B$89-1)/Rate_calculator!$B$93)+(Rate_calculator!$B$5*J16*(Rate_calculator!$B$90+Rate_calculator!$B$18/Rate_calculator!$B$93-Rate_calculator!$B$18*Rate_calculator!$B$90/Rate_calculator!$B$93-1))+(Rate_calculator!$B$6*J16*(Rate_calculator!$B$90-1))) -> 8383.5157 | D16: =IF(A16<=Rate_calculator!$B$22, Rate_calculator!$B$7*(1-K16), Rate_calculator!$B$7*K16*(Rate_calculator!$B$91-1)) -> 1906.0092 | E16: =IF(A16<=Rate_calculator!$B$22, Rate_calculator!$B$8*(1-L16), (Rate_calculator!$B$8*L16*(Rate_calculator!$B$92-1))) -> 0 | F16: =B16+C16+D16+E16+Rate_calculator!$B$26 -> 63092.324 | G16: =Rate_calculator!$B$26 -> 50 | I16: =EXP(-Rate_calculator!$B$17*A16) -> 0.64831467 | J16: =EXP(-Rate_calculator!$B$18*A16) -> 0.78680689 | K16: =EXP(-Rate_calculator!$B$19*A16) -> 0.9998094 | L16: =EXP(-Rate_calculator!$B$20*A16) -> 0.86437019 | M16: =J16-I16 -> 0.13849222
... A504: =A503+(Rate_calculator!$B$22+Rate_calculator!$B$23)/Rate_calculator!$B$24 -> 22.00001 | B504: =IF(A504<=Rate_calculator!$B$22, Rate_calculator!$B$5*(1-I504), Rate_calculator!$B$5*I504*(Rate_calculator!$B$89-1)) -> 0.0089827071 | C504: =IF(A504<=Rate_calculator!$B$22, (Rate_calculator!$B$5+Rate_calculator!$B$6)*(1-J504)+Rate_calculator!$B$5*Rate_calculator!$B$18/Rate_calculator!$B$93*M504, (Rate_calculator!$B$5*Rate_calculator!$B$18*I504*(Rate_calculator!$B$89-1)/Rate_calculator!$B$93)+(Rate_calculator!$B$5*J504*(Rate_calculator!$B$90+Rate_calculator!$B$18/Rate_calculator!$B$93-Rate_calculator!$B$18*Rate_calculator!$B$90/Rate_calculator!$B$93-1))+(Rate_calculator!$B$6*J504*(Rate_calculator!$B$90-1))) -> 23.445493 | D504: =IF(A504<=Rate_calculator!$B$22, Rate_calculator!$B$7*(1-K504), Rate_calculator!$B$7*K504*(Rate_calculator!$B$91-1)) -> 7165.7511 | E504: =IF(A504<=Rate_calculator!$B$22, Rate_calculator!$B$8*(1-L504), (Rate_calculator!$B$8*L504*(Rate_calculator!$B$92-1))) -> 0 | F504: =B504+C504+D504+E504+Rate_calculator!$B$26 -> 7239.2056 | G504: =Rate_calculator!$B$26 -> 50 | I504: =EXP(-Rate_calculator!$B$17*A504) -> 1.4384302e-08 | J504: =EXP(-Rate_calculator!$B$18*A504) -> 4.5840921e-05 | K504: =EXP(-Rate_calculator!$B$19*A504) -> 0.99208914 | L504: =EXP(-Rate_calculator!$B$20*A504) -> 0.0023043034 | M504: =J504-I504 -> 4.5826536e-05
